Workbook
Name _Ref19613010: #REF!

Sheet Hours estimate
A1: Data Security Envisioning Workshop | I1: Data Security Check - Mandatory Scope
A2: Estimated partner effort | I2: Estimated partner effort - Mandatory Scope
F3: Delivery | N3: Delivery
B4: Pre-engagement call | F4: 1.5 | J4: =+'Version information'!$I$2 -> Step 1 | K4: =+'Version information'!$L$2 -> Kick-off meeting
B5: Data Security Check - default scope | F5: =+N40 -> 22.7 | K5: =+'Version information'!$K$2 -> Core Activities | N5: 1.5
B6: Present & discuss the Data Security Check findings | F6: 2 | K6: =+$A$45 -> Exchange Online | N6: =+F47 -> 0.5
B7: Microsoft Purview portfolio overview | F7: 2 | K7: =+$I$45 -> SharePoint Online | N7: =+N47 -> 0.5
B8: Recommendations and next steps | F8: 2 | G8: + | K8: =+$Q$45 -> Teams | N8: =+V47 -> 0.5
B9: Total Estimated partner effort | F9: =SUM(F4:F8) -> 30.2 | K9: =+$Y$45 -> Insider Risk Management | N9: =+AD47 -> 1
J10: =+'Version information'!$I$3 -> Step 2 | K10: =+'Version information'!$L$3 -> Acquire and assign licenses
K11: =+'Version information'!$K$3 -> Core Activities | N11: 0.5
A12: Data Security Envisioning Workshop - TO BE USED IN STATEMENT OF WORK | K12: =+$A$45 -> Exchange Online | N12: =+F48 -> 0
A13: Estimated partner effort | K13: =+$I$45 -> SharePoint Online | N13: =+N48 -> 0
F14: Delivery | K14: =+$Q$45 -> Teams | N14: =+V48 -> 0
B15: Pre-engagement call | F15: =+F4 -> 1.5 | K15: =+$Y$45 -> Insider Risk Management | N15: =+AD48 -> 0
B16: Data Security Check - default scope | F16: =+F5 -> 22.7 | J16: =+'Version information'!$I$4 -> Step 3 | K16: =+'Version information'!$L$4 -> Setup and Configuration
B17: Select included module. | F17: =VLOOKUP(B17,'Version information'!S2:T10,2,FALSE) -> x.x Hrs | K17: =+'Version information'!$K$4 -> Core Activities | N17: 1
B18: Present & discuss the Data Security Check findings | F18: =+F6 -> 2 | K18: =+$A$45 -> Exchange Online | N18: =+F49 -> 1
B19: Microsoft Purview portfolio overview | F19: =+F7 -> 2 | K19: =+$I$45 -> SharePoint Online | N19: =+N49 -> 1
B20: Recommendations and next steps | F20: =+F8 -> 2 | G20: + | K20: =+$Q$45 -> Teams | N20: =+V49 -> 1
B21: Total Estimated partner effort | F21: =SUM(F15:F20) -> 30.2 | K21: =+$Y$45 -> Insider Risk Management | N21: =+AD49 -> 2
J22: =+'Version information'!$I$5 -> Step 4 | K22: =+'Version information'!$L$5 -> Analyze the findings
K23: =+'Version information'!$K$5 -> Core Activities | N23: 0
K24: =+$A$45 -> Exchange Online | N24: =+F50 -> 1
K25: =+$I$45 -> SharePoint Online | N25: =+N50 -> 1
K26: =+$Q$45 -> Teams | N26: =+V50 -> 1
K27: =+$Y$45 -> Insider Risk Management | N27: =+AD50 -> 1.5
J28: =+'Version information'!$I$6 -> Step 5 | K28: =+'Version information'!$L$6 -> Report and recommendations write-up
K29: =+'Version information'!$K$6 -> Core Activities | N29: 1.5
K30: =+$A$45 -> Exchange Online | N30: =+F51 -> 1
K31: =+$I$45 -> SharePoint Online | N31: =+N51 -> 1
K32: =+$Q$45 -> Teams | N32: =+V51 -> 1
K33: =+$Y$45 -> Insider Risk Management | N33: =+AD51 -> 1
J34: =+'Version information'!$I$7 -> Step 6 | K34: =+'Version information'!$L$7 -> Decommision
K35: =+'Version information'!$K$7 -> Core Activities | N35: 0.2
K36: =+$A$45 -> Exchange Online | N36: =+F52 -> 0.5
K37: =+$I$45 -> SharePoint Online | N37: =+N52 -> 0.5
K38: =+$Q$45 -> Teams | N38: =+V52 -> 0.5
K39: =+$Y$45 -> Insider Risk Management | N39: =+AD52 -> 0.5 | O39: +
J40: Estimated effort | N40: =SUM(N4:N39) -> 22.7
...

Sheet Version information
A1: Version | B1: Date | C1: Author | D1: Changes | I1: Steps and step names | S1: Module | T1: Hours
A2: 1.0 | B2: November 2019 | C2: François van Hemert | D2: First published v1 release | I2: Step 1 | J2: Additional effort - Kick-off meeting | K2: Core Activities | L2: Kick-off meeting | M2: Estimated additional effort for preparation | O2: Additional effort - | S2: Select included module. | T2: x.x Hrs
A3: 2.0 | B3: June 2020 | C3: François van Hemert | D3: First published v2 release | I3: Step 2 | J3: Additional effort - Acquire and assign licenses | K3: Core Activities | L3: Acquire and assign licenses | M3: Estimated additional effort for delivery | S3: =+'Hours estimate'!A57 -> Compliance Manager | T3: =+'Hours estimate'!F66 -> 4
A4: 2.1 | B4: 44136 | C4: François van Hemert | D4: Maintenance release, minor updates. | I4: Step 3 | J4: Additional effort - Setup and Configuration | K4: Core Activities | L4: Setup and Configuration | M4: Estimated total effort | S4: =+'Hours estimate'!I57 -> On-premises data scanner | T4: =+'Hours estimate'!N66 -> 8
A5: 3.0 | B5: January 2021 | C5: François van Hemert | D5: Modular release, added Compliance Manager, removed CIE | I5: Step 4 | J5: Additional effort - Analyze the findings | K5: Core Activities | L5: Analyze the findings | S5: =+'Hours estimate'!Q57 -> Windows endpoints | T5: =+'Hours estimate'!V66 -> 8
A6: 3.1 | B6: February 2021 | C6: François van Hemert | D6: Added Teams Data Loss Prevention as optional module | I6: Step 5 | J6: Additional effort - Report and recommendations write-up | K6: Core Activities | L6: Report and recommendations write-up | S6: =+'Hours estimate'!Y57 -> Communication Compliance | T6: =+'Hours estimate'!AD66 -> 4
A7: 4.0 | B7: June 2021 | C7: François van Hemert | D7: Workshop split, update to align with new narrative, rebranding, updates to guidance and organized around data repositories. | I7: Step 6 | J7: Additional effort - Decommision | K7: Core Activities | L7: Decommision | S7: Purview for AI | T7: =+'Hours estimate'!F78 -> 8
A8: 4.1 | B8: October 2021 | C8: François van Hemert | D8: Update with Compliance Manager Premium Assessments
A9: 4.2 | B9: 44743 | C9: François van Hemert | D9: Purview branding update, step-by-step guidance update to align with changes M365
A10: 4,2,2 | B10: 44927 | C10: François van Hemert | D10: Updated version number to align with kit, no content updates
A11: 6.0 | B11: 45139 | C11: François van Hemert | D11: Workshop merge, align with FY24 solution play.
A12: 6.5 | B12: Juli 2024 | C12: François van Hemert | D12: Update step guidance, align with FY25 solution play
A13: 6.6 | B13: 45566 | C13: François van Hemert | D13: Version number update for alignment, no content changes
A14: 7.0 | B14: 45658 | C14: François van Hemert | D14: Added Data security for generative AI module
A15: 7.1 | B15: 45778 | C15: François van Hemert | D15: Version number update, no further changes
A16: 8.0 | B16: Juli 2025 | C16: François van Hemert | D16: Update to align with current product features and functionality (evergreen), update name, update branding.
A17: 8.5 | B17: 46023 | C17: François van Hemert | D17: Version number update, no further changes
